Workbook

Sheet Sheet 1 - Amortization & Charts
A1: MINI-PROJECT: THE TWO-LOAN COMPARISON
A3: Borrower needs $5,000 for 2 years, monthly payments. All rates are simple annual rates divided by 12.
A4: Borrower Loan Requirement
A5: Cash ($) | C5: 5000
A6: Term (months) | C6: 24
B8: Loans Options
B9: Bank : Chase Bank | D9: Bank : Wells Fargo Bank
A10: Simple annual rate | B10: 0.1 | D10: 0.07
A11: Monthly rate | B11: =B10/12 -> 0.0083333333 | D11: =D10/12 -> 0.0058333333
A12: Origination fee (% of loan) | B12: 0 | D12: 0.02
A13: Amount financed ($) | B13: =$C$5*(1+$B$12) -> 5000 | D13: =$C$5*(1+$D$12) -> 5100 | F13: Note: the fee is financed, so Wells Fargo lends $5,100 of principal while the borrower receives $5,000 in cash.
A14: Monthly Payment | B14: =$B$13*$B$11/(1-(1/(1+$B$11)^$C$6)) -> 230.72463 | D14: =$D$13*$D$11/(1-(1/(1+$D$11)^$C$6)) -> 228.34015
A17: LOAN A - CHASE BANK: 24-month amortization | I17: LOAN B - WELLS FARGO BANK: 24-month amortization
A18: Period i | B18: Beginning balance V(i) ($) | C18: Interest r*V(i) ($) | D18: Payment C ($) | E18: Principal reduction C - r*V(i) ($) | F18: Ending balance V(i+1) ($) | I18: Period i | J18: Beginning balance V(i) ($) | K18: Interest r*V(i) ($) | L18: Payment C ($) | M18: Principal reduction C - r*V(i) ($) | N18: Ending balance V(i+1) ($)
A19: 1 | B19: =$B13 -> 5000 | C19: =$B19*$B$11 -> 41.666667 | D19: =$B$14 -> 230.72463 | E19: =$D19-$C19 -> 189.05797 | F19: =$B19-$E19 -> 4810.942 | I19: 1 | J19: =$D$13 -> 5100 | K19: =$J19*$D$11 -> 29.75 | L19: =$D$14 -> 228.34015 | M19: =$L19-$K19 -> 198.59015 | N19: =$J19-$M19 -> 4901.4098
A20: 2 | B20: =F19 -> 4810.942 | C20: =$B20*$B$11 -> 40.091184 | D20: =$B$14 -> 230.72463 | E20: =$D20-$C20 -> 190.63345 | F20: =$B20-$E20 -> 4620.3086 | I20: 2 | J20: =N19 -> 4901.4098 | K20: =$J20*$D$11 -> 28.591557 | L20: =$D$14 -> 228.34015 | M20: =$L20-$K20 -> 199.7486 | N20: =$J20-$M20 -> 4701.6613
A21: 3 | B21: =F20 -> 4620.3086 | C21: =$B21*$B$11 -> 38.502572 | D21: =$B$14 -> 230.72463 | E21: =$D21-$C21 -> 192.22206 | F21: =$B21-$E21 -> 4428.0865 | I21: 3 | J21: =N20 -> 4701.6613 | K21: =$J21*$D$11 -> 27.426357 | L21: =$D$14 -> 228.34015 | M21: =$L21-$K21 -> 200.9138 | N21: =$J21-$M21 -> 4500.7475
A22: 4 | B22: =F21 -> 4428.0865 | C22: =$B22*$B$11 -> 36.900721 | D22: =$B$14 -> 230.72463 | E22: =$D22-$C22 -> 193.82391 | F22: =$B22-$E22 -> 4234.2626 | I22: 4 | J22: =N21 -> 4500.7475 | K22: =$J22*$D$11 -> 26.25436 | L22: =$D$14 -> 228.34015 | M22: =$L22-$K22 -> 202.08579 | N22: =$J22-$M22 -> 4298.6617
A23: 5 | B23: =F22 -> 4234.2626 | C23: =$B23*$B$11 -> 35.285522 | D23: =$B$14 -> 230.72463 | E23: =$D23-$C23 -> 195.43911 | F23: =$B23-$E23 -> 4038.8235 | I23: 5 | J23: =N22 -> 4298.6617 | K23: =$J23*$D$11 -> 25.075526 | L23: =$D$14 -> 228.34015 | M23: =$L23-$K23 -> 203.26463 | N23: =$J23-$M23 -> 4095.397
A24: 6 | B24: =F23 -> 4038.8235 | C24: =$B24*$B$11 -> 33.656863 | D24: =$B$14 -> 230.72463 | E24: =$D24-$C24 -> 197.06777 | F24: =$B24-$E24 -> 3841.7557 | I24: 6 | J24: =N23 -> 4095.397 | K24: =$J24*$D$11 -> 23.889816 | L24: =$D$14 -> 228.34015 | M24: =$L24-$K24 -> 204.45034 | N24: =$J24-$M24 -> 3890.9467
A25: 7 | B25: =F24 -> 3841.7557 | C25: =$B25*$B$11 -> 32.014631 | D25: =$B$14 -> 230.72463 | E25: =$D25-$C25 -> 198.71 | F25: =$B25-$E25 -> 3643.0457 | I25: 7 | J25: =N24 -> 3890.9467 | K25: =$J25*$D$11 -> 22.697189 | L25: =$D$14 -> 228.34015 | M25: =$L25-$K25 -> 205.64296 | N25: =$J25-$M25 -> 3685.3037
A26: 8 | B26: =F25 -> 3643.0457 | C26: =$B26*$B$11 -> 30.358714 | D26: =$B$14 -> 230.72463 | E26: =$D26-$C26 -> 200.36592 | F26: =$B26-$E26 -> 3442.6798 | I26: 8 | J26: =N25 -> 3685.3037 | K26: =$J26*$D$11 -> 21.497605 | L26: =$D$14 -> 228.34015 | M26: =$L26-$K26 -> 206.84255 | N26: =$J26-$M26 -> 3478.4612
A27: 9 | B27: =F26 -> 3442.6798 | C27: =$B27*$B$11 -> 28.688998 | D27: =$B$14 -> 230.72463 | E27: =$D27-$C27 -> 202.03563 | F27: =$B27-$E27 -> 3240.6442 | I27: 9 | J27: =N26 -> 3478.4612 | K27: =$J27*$D$11 -> 20.291024 | L27: =$D$14 -> 228.34015 | M27: =$L27-$K27 -> 208.04913 | N27: =$J27-$M27 -> 3270.4121
A28: 10 | B28: =F27 -> 3240.6442 | C28: =$B28*$B$11 -> 27.005368 | D28: =$B$14 -> 230.72463 | E28: =$D28-$C28 -> 203.71926 | F28: =$B28-$E28 -> 3036.9249 | I28: 10 | J28: =N27 -> 3270.4121 | K28: =$J28*$D$11 -> 19.077404 | L28: =$D$14 -> 228.34015 | M28: =$L28-$K28 -> 209.26275 | N28: =$J28-$M28 -> 3061.1493
A29: 11 | B29: =F28 -> 3036.9249 | C29: =$B29*$B$11 -> 25.307708 | D29: =$B$14 -> 230.72463 | E29: =$D29-$C29 -> 205.41692 | F29: =$B29-$E29 -> 2831.508 | I29: 11 | J29: =N28 -> 3061.1493 | K29: =$J29*$D$11 -> 17.856704 | L29: =$D$14 -> 228.34015 | M29: =$L29-$K29 -> 210.48345 | N29: =$J29-$M29 -> 2850.6659
A30: 12 | B30: =F29 -> 2831.508 | C30: =$B30*$B$11 -> 23.5959 | D30: =$B$14 -> 230.72463 | E30: =$D30-$C30 -> 207.12873 | F30: =$B30-$E30 -> 2624.3793 | I30: 12 | J30: =N29 -> 2850.6659 | K30: =$J30*$D$11 -> 16.628884 | L30: =$D$14 -> 228.34015 | M30: =$L30-$K30 -> 211.71127 | N30: =$J30-$M30 -> 2638.9546
A31: 13 | B31: =F30 -> 2624.3793 | C31: =$B31*$B$11 -> 21.869827 | D31: =$B$14 -> 230.72463 | E31: =$D31-$C31 -> 208.8548 | F31: =$B31-$E31 -> 2415.5245 | I31: 13 | J31: =N30 -> 2638.9546 | K31: =$J31*$D$11 -> 15.393902 | L31: =$D$14 -> 228.34015 | M31: =$L31-$K31 -> 212.94625 | N31: =$J31-$M31 -> 2426.0083
... A42: 24 | B42: =F41 -> 228.81782 | C42: =$B42*$B$11 -> 1.9068151 | D42: =$B$14 -> 230.72463 | E42: =$D42-$C42 -> 228.81782 | F42: =$B42-$E42 -> -2.4385827e-11 | I42: 24 | J42: =N41 -> 227.01589 | K42: =$J42*$D$11 -> 1.3242594 | L42: =$D$14 -> 228.34015 | M42: =$L42-$K42 -> 227.01589 | N42: =$J42-$M42 -> 1.8900437e-11
A43: Total | C43: =SUM(C19:C42) -> 537.39116 | D43: =SUM(D19:D42) -> 5537.3912 | E43: =SUM(E19:E42) -> 5000 | I43: Total | K43: =SUM(K19:K42) -> 380.16368 | L43: =SUM(L19:L42) -> 5480.1637 | M43: =SUM(M19:M42) -> 5100
A44: =IF(AND(ABS(F42)<0.005,ABS(N42)<0.005),"PASS - both loans amortize to $0.00","CHECK") -> PASS - both loans amortize to $0.00

Sheet Sheet 2 - Payoff Analysis
A1: MINI-PROJECT: Early Payoff Analysis (payoff balance vs. PV of remaining payments)
A3: Borrower needs $5,000 for 2 years, monthly payments. All rates are simple annual rates divided by 12.
A4: Borrower Loan Requirement
A5: Cash ($) | C5: 5000
A6: Term (months) | C6: 24
B8: Loans Options
B9: Bank : Chase Bank | D9: Bank : Wells Fargo Bank
A10: Simple annual rate | B10: 0.1 | D10: 0.07
A11: Monthly rate | B11: =B10/12 -> 0.0083333333 | D11: =D10/12 -> 0.0058333333
A12: Origination fee (% of loan) | B12: 0 | D12: 0.02
A13: Amount financed ($) | B13: =$C$5*(1+$B$12) -> 5000 | D13: =$C$5*(1+$D$12) -> 5100 | F13: Note: the fee is financed, so Wells Fargo lends $5,100 of principal while the borrower receives $5,000 in cash.
A14: Monthly Payment | B14: =$B$13*$B$11/(1-(1/(1+$B$11)^$C$6)) -> 230.72463 | D14: =$D$13*$D$11/(1-(1/(1+$D$11)^$C$6)) -> 228.34015
A16: DISCOUNT RATE
A17: Simple annual rate | C17: =B10 -> 0.1 | F17: Note: As per Part © both loan are discounted at chase bank rate
A18: Monthly rate | C18: =B11 -> 0.0083333333
A21: LOAN A - CHASE BANK | G21: LOAN B - WELLS FARGO BANK
A22: Period i | B22: Chase - payoff balance ($) | C22: Chase - PV of remaining payments ($) | D22: Chase - balance less PV ($) | G22: Period i | H22: Wells Fargo - payoff balance ($) | I22: Wells Fargo - PV of remaining payments ($) | J22: Wells Fargo - balance less PV ($)
A23: 1 | B23: ='Sheet 1 - Amortization & Charts'!$F19 -> 4810.942 | C23: =IF($A23>=$C$6,0,($B$14)*(1-(1+$C$18)^(-($C$6-$A23)))/$C$18) -> 4810.942 | D23: =B23-C23 -> 0 | G23: 1 | H23: ='Sheet 1 - Amortization & Charts'!$N19 -> 4901.4098 | I23: =IF($A23>=$C$6,0,($D$14)*(1-(1+$C$18)^(-($C$6-$A23)))/$C$18) -> 4761.2222 | J23: =H23-I23 -> 140.18763
A24: 2 | B24: ='Sheet 1 - Amortization & Charts'!$F20 -> 4620.3086 | C24: =IF($A24>=$C$6,0,($B$14)*(1-(1+$C$18)^(-($C$6-$A24)))/$C$18) -> 4620.3086 | D24: =B24-C24 -> 0 | G24: 2 | H24: ='Sheet 1 - Amortization & Charts'!$N20 -> 4701.6613 | I24: =IF($A24>=$C$6,0,($D$14)*(1-(1+$C$18)^(-($C$6-$A24)))/$C$18) -> 4572.5589 | J24: =H24-I24 -> 129.10234
A25: 3 | B25: ='Sheet 1 - Amortization & Charts'!$F21 -> 4428.0865 | C25: =IF($A25>=$C$6,0,($B$14)*(1-(1+$C$18)^(-($C$6-$A25)))/$C$18) -> 4428.0865 | D25: =B25-C25 -> 0 | G25: 3 | H25: ='Sheet 1 - Amortization & Charts'!$N21 -> 4500.7475 | I25: =IF($A25>=$C$6,0,($D$14)*(1-(1+$C$18)^(-($C$6-$A25)))/$C$18) -> 4382.3234 | J25: =H25-I25 -> 118.42403
A26: 4 | B26: ='Sheet 1 - Amortization & Charts'!$F22 -> 4234.2626 | C26: =IF($A26>=$C$6,0,($B$14)*(1-(1+$C$18)^(-($C$6-$A26)))/$C$18) -> 4234.2626 | D26: =B26-C26 -> 0 | G26: 4 | H26: ='Sheet 1 - Amortization & Charts'!$N22 -> 4298.6617 | I26: =IF($A26>=$C$6,0,($D$14)*(1-(1+$C$18)^(-($C$6-$A26)))/$C$18) -> 4190.5026 | J26: =H26-I26 -> 108.15903
A27: 5 | B27: ='Sheet 1 - Amortization & Charts'!$F23 -> 4038.8235 | C27: =IF($A27>=$C$6,0,($B$14)*(1-(1+$C$18)^(-($C$6-$A27)))/$C$18) -> 4038.8235 | D27: =B27-C27 -> -6.8212103e-12 | G27: 5 | H27: ='Sheet 1 - Amortization & Charts'!$N23 -> 4095.397 | I27: =IF($A27>=$C$6,0,($D$14)*(1-(1+$C$18)^(-($C$6-$A27)))/$C$18) -> 3997.0833 | J27: =H27-I27 -> 98.313704
A28: 6 | B28: ='Sheet 1 - Amortization & Charts'!$F24 -> 3841.7557 | C28: =IF($A28>=$C$6,0,($B$14)*(1-(1+$C$18)^(-($C$6-$A28)))/$C$18) -> 3841.7557 | D28: =B28-C28 -> -6.3664629e-12 | G28: 6 | H28: ='Sheet 1 - Amortization & Charts'!$N24 -> 3890.9467 | I28: =IF($A28>=$C$6,0,($D$14)*(1-(1+$C$18)^(-($C$6-$A28)))/$C$18) -> 3802.0522 | J28: =H28-I28 -> 88.894493
A29: 7 | B29: ='Sheet 1 - Amortization & Charts'!$F25 -> 3643.0457 | C29: =IF($A29>=$C$6,0,($B$14)*(1-(1+$C$18)^(-($C$6-$A29)))/$C$18) -> 3643.0457 | D29: =B29-C29 -> -5.9117156e-12 | G29: 7 | H29: ='Sheet 1 - Amortization & Charts'!$N25 -> 3685.3037 | I29: =IF($A29>=$C$6,0,($D$14)*(1-(1+$C$18)^(-($C$6-$A29)))/$C$18) -> 3605.3958 | J29: =H29-I29 -> 79.907913
A30: 8 | B30: ='Sheet 1 - Amortization & Charts'!$F26 -> 3442.6798 | C30: =IF($A30>=$C$6,0,($B$14)*(1-(1+$C$18)^(-($C$6-$A30)))/$C$18) -> 3442.6798 | D30: =B30-C30 -> -8.1854523e-12 | G30: 8 | H30: ='Sheet 1 - Amortization & Charts'!$N26 -> 3478.4612 | I30: =IF($A30>=$C$6,0,($D$14)*(1-(1+$C$18)^(-($C$6-$A30)))/$C$18) -> 3407.1006 | J30: =H30-I30 -> 71.360553
A31: 9 | B31: ='Sheet 1 - Amortization & Charts'!$F27 -> 3240.6442 | C31: =IF($A31>=$C$6,0,($B$14)*(1-(1+$C$18)^(-($C$6-$A31)))/$C$18) -> 3240.6442 | D31: =B31-C31 -> -6.3664629e-12 | G31: 9 | H31: ='Sheet 1 - Amortization & Charts'!$N27 -> 3270.4121 | I31: =IF($A31>=$C$6,0,($D$14)*(1-(1+$C$18)^(-($C$6-$A31)))/$C$18) -> 3207.153 | J31: =H31-I31 -> 63.259072
A32: 10 | B32: ='Sheet 1 - Amortization & Charts'!$F28 -> 3036.9249 | C32: =IF($A32>=$C$6,0,($B$14)*(1-(1+$C$18)^(-($C$6-$A32)))/$C$18) -> 3036.9249 | D32: =B32-C32 -> -7.2759576e-12 | G32: 10 | H32: ='Sheet 1 - Amortization & Charts'!$N28 -> 3061.1493 | I32: =IF($A32>=$C$6,0,($D$14)*(1-(1+$C$18)^(-($C$6-$A32)))/$C$18) -> 3005.5391 | J32: =H32-I32 -> 55.6102
A33: 11 | B33: ='Sheet 1 - Amortization & Charts'!$F29 -> 2831.508 | C33: =IF($A33>=$C$6,0,($B$14)*(1-(1+$C$18)^(-($C$6-$A33)))/$C$18) -> 2831.508 | D33: =B33-C33 -> -7.2759576e-12 | G33: 11 | H33: ='Sheet 1 - Amortization & Charts'!$N29 -> 2850.6659 | I33: =IF($A33>=$C$6,0,($D$14)*(1-(1+$C$18)^(-($C$6-$A33)))/$C$18) -> 2802.2451 | J33: =H33-I33 -> 48.420745
A34: 12 | B34: ='Sheet 1 - Amortization & Charts'!$F30 -> 2624.3793 | C34: =IF($A34>=$C$6,0,($B$14)*(1-(1+$C$18)^(-($C$6-$A34)))/$C$18) -> 2624.3793 | D34: =B34-C34 -> -1.4097168e-11 | G34: 12 | H34: ='Sheet 1 - Amortization & Charts'!$N30 -> 2638.9546 | I34: =IF($A34>=$C$6,0,($D$14)*(1-(1+$C$18)^(-($C$6-$A34)))/$C$18) -> 2597.257 | J34: =H34-I34 -> 41.697587
... A46: 24 | B46: ='Sheet 1 - Amortization & Charts'!$F42 -> -2.4385827e-11 | C46: =IF($A46>=$C$6,0,($B$14)*(1-(1+$C$18)^(-($C$6-$A46)))/$C$18) -> 0 | D46: =B46-C46 -> -2.4385827e-11 | G46: 24 | H46: ='Sheet 1 - Amortization & Charts'!$N42 -> 1.8900437e-11 | I46: =IF($A46>=$C$6,0,($D$14)*(1-(1+$C$18)^(-($C$6-$A46)))/$C$18) -> 0 | J46: =H46-I46 -> 1.8900437e-11
A48: The payoff balance and the PV of remaining payments answer two different questions: what the bank demands to close the loan today, versus what the payments you escape are worth at your opportunity cost of 10%.
A49: For Chase the two are identical at every date (column D is $0.00 throughout), because an amortising balance is by construction the PV of its remaining payments discounted at the loan's own rate. Prepaying Chase is therefore a zero-NPV transaction — no payoff date is better than another.
A50: For Wells Fargo the balance exceeds the PV at every date, by $140.19 in month 1 falling to $0.00 by month 24. A 7% payment stream discounted at 10% is worth less than the balance that generated it, and that gap is the value of borrowing below market.
A51: Conclusion: do not prepay the Wells Fargo loan from funds that could earn 10%; settling at par destroys the rate advantage. The general rule is to prepay only when your discount rate is below the contract rate.

Sheet Sheet 3 - Bank's View
A1: MINI-PROJECT: The Bank's View: Wells Fargo's portfolio of 1,000 loans
A4: Wells Fargo funds the loans at 2%/year, loses 0.5% of the pool per month to default (zero recovery) and 1% of the pool per month to prepayment (paid off in full).
A5: Number of loans in the pool | B5: 1000
A6: Cash advanced per borrower ($) | B6: 5000
A7: Simple annual rate contract rate | B7: 0.07
A8: Monthly rate contract rate | B8: =B7/12 -> 0.0058333333
A9: Origination fee (% of loan, financed) | B9: 0.02
A10: Amount financed per loan ($) | B10: =B6*(1+B9) -> 5100
A11: Term (months) | B11: 24
A12: Monthly payment per loan ($) | B12: =B10*B8/(1-(1/((1+B8)^B11))) -> 228.34015
A13: Wells Fargo cost of funds - annual | B13: 0.02
A14: Wells Fargo cost of funds - monthly | B14: =B13/12 -> 0.0016666667
A15: Default rate (% of pool per month, zero recovery) | B15: 0.005
A16: Prepayment rate (% of pool per month, paid in full) | B16: 0.01
A17: Monthly survival factor | B17: =1-B16-B15 -> 0.985
A18: Total cash advanced by the bank ($) | B18: =B6*B5 -> 5000000
A21: Month t | B21: Loans at start | C21: Defaults (loans) | D21: Prepayments (loans) | E21: Loans at end | F21: Beginning balance per loan ($) | G21: Interest per loan ($) | H21: Scheduled principal per loan ($) | I21: AGGREGATE interest collected ($) | J21: AGGREGATE scheduled principal ($) | K21: Ending balance per loan ($) | L21: AGGREGATE prepayment principal ($) | M21: TOTAL cash to bank ($) | N21: Discount factor | O21: PV of cash ($)
A22: 1 | B22: =$B$5 -> 1000 | C22: =$B22*$B$15 -> 5 | D22: =$B22*$B$16 -> 10 | E22: =$B22-$C22-$D22 -> 985 | F22: =$B$10 -> 5100 | G22: =$F22*$B$8 -> 29.75 | H22: =$B$12-$G22 -> 198.59015 | I22: =G22*(B22-C22) -> 29601.25 | J22: =$H22*($B22-$C22) -> 197597.2 | K22: =F22-H22 -> 4901.4098 | L22: =$D22*$K22 -> 49014.098 | M22: =$I22+$J22+$L22 -> 276212.55 | N22: =1/(1+$B$14)^A22 -> 0.99833611 | O22: =$M22*$N22 -> 275752.96
A23: 2 | B23: =$E22 -> 985 | C23: =$B23*$B$15 -> 4.925 | D23: =$B23*$B$16 -> 9.85 | E23: =$B23-$C23-$D23 -> 970.225 | F23: =K22 -> 4901.4098 | G23: =$F23*$B$8 -> 28.591557 | H23: =$B$12-$G23 -> 199.7486 | I23: =G23*(B23-C23) -> 28021.871 | J23: =$H23*($B23-$C23) -> 195768.61 | K23: =F23-H23 -> 4701.6613 | L23: =$D23*$K23 -> 46311.363 | M23: =$I23+$J23+$L23 -> 270101.84 | N23: =1/(1+$B$14)^A23 -> 0.99667498 | O23: =$M23*$N23 -> 269203.75
A24: 3 | B24: =$E23 -> 970.225 | C24: =$B24*$B$15 -> 4.851125 | D24: =$B24*$B$16 -> 9.70225 | E24: =$B24-$C24-$D24 -> 955.67162 | F24: =K23 -> 4701.6613 | G24: =$F24*$B$8 -> 27.426357 | H24: =$B$12-$G24 -> 200.9138 | I24: =G24*(B24-C24) -> 26476.689 | J24: =$H24*($B24-$C24) -> 193956.93 | K24: =F24-H24 -> 4500.7475 | L24: =$D24*$K24 -> 43667.377 | M24: =$I24+$J24+$L24 -> 264101 | N24: =1/(1+$B$14)^A24 -> 0.99501662 | O24: =$M24*$N24 -> 262784.88
A25: 4 | B25: =$E24 -> 955.67162 | C25: =$B25*$B$15 -> 4.7783581 | D25: =$B25*$B$16 -> 9.5567162 | E25: =$B25-$C25-$D25 -> 941.33655 | F25: =K24 -> 4500.7475 | G25: =$F25*$B$8 -> 26.25436 | H25: =$B$12-$G25 -> 202.08579 | I25: =G25*(B25-C25) -> 24965.094 | J25: =$H25*($B25-$C25) -> 192162.02 | K25: =F25-H25 -> 4298.6617 | L25: =$D25*$K25 -> 41081.09 | M25: =$I25+$J25+$L25 -> 258208.2 | N25: =1/(1+$B$14)^A25 -> 0.99336102 | O25: =$M25*$N25 -> 256493.96
A26: 5 | B26: =$E25 -> 941.33655 | C26: =$B26*$B$15 -> 4.7066828 | D26: =$B26*$B$16 -> 9.4133655 | E26: =$B26-$C26-$D26 -> 927.2165 | F26: =K25 -> 4298.6617 | G26: =$F26*$B$8 -> 25.075526 | H26: =$B$12-$G26 -> 203.26463 | I26: =G26*(B26-C26) -> 23486.487 | J26: =$H26*($B26-$C26) -> 190383.72 | K26: =F26-H26 -> 4095.397 | L26: =$D26*$K26 -> 38551.469 | M26: =$I26+$J26+$L26 -> 252421.68 | N26: =1/(1+$B$14)^A26 -> 0.99170817 | O26: =$M26*$N26 -> 250328.64
A27: 6 | B27: =$E26 -> 927.2165 | C27: =$B27*$B$15 -> 4.6360825 | D27: =$B27*$B$16 -> 9.272165 | E27: =$B27-$C27-$D27 -> 913.30825 | F27: =K26 -> 4095.397 | G27: =$F27*$B$8 -> 23.889816 | H27: =$B$12-$G27 -> 204.45034 | I27: =G27*(B27-C27) -> 22040.277 | J27: =$H27*($B27-$C27) -> 188621.88 | K27: =F27-H27 -> 3890.9467 | L27: =$D27*$K27 -> 36077.5 | M27: =$I27+$J27+$L27 -> 246739.65 | N27: =1/(1+$B$14)^A27 -> 0.99005808 | O27: =$M27*$N27 -> 244286.59
A28: 7 | B28: =$E27 -> 913.30825 | C28: =$B28*$B$15 -> 4.5665413 | D28: =$B28*$B$16 -> 9.1330825 | E28: =$B28-$C28-$D28 -> 899.60863 | F28: =K27 -> 3890.9467 | G28: =$F28*$B$8 -> 22.697189 | H28: =$B$12-$G28 -> 205.64296 | I28: =G28*(B28-C28) -> 20625.882 | J28: =$H28*($B28-$C28) -> 186876.34 | K28: =F28-H28 -> 3685.3037 | L28: =$D28*$K28 -> 33658.183 | M28: =$I28+$J28+$L28 -> 241160.41 | N28: =1/(1+$B$14)^A28 -> 0.98841072 | O28: =$M28*$N28 -> 238365.53
A29: 8 | B29: =$E28 -> 899.60863 | C29: =$B29*$B$15 -> 4.4980432 | D29: =$B29*$B$16 -> 8.9960863 | E29: =$B29-$C29-$D29 -> 886.1145 | F29: =K28 -> 3685.3037 | G29: =$F29*$B$8 -> 21.497605 | H29: =$B$12-$G29 -> 206.84255 | I29: =G29*(B29-C29) -> 19242.734 | J29: =$H29*($B29-$C29) -> 185146.96 | K29: =F29-H29 -> 3478.4612 | L29: =$D29*$K29 -> 31292.537 | M29: =$I29+$J29+$L29 -> 235682.23 | N29: =1/(1+$B$14)^A29 -> 0.98676611 | O29: =$M29*$N29 -> 232563.23
A30: 9 | B30: =$E29 -> 886.1145 | C30: =$B30*$B$15 -> 4.4305725 | D30: =$B30*$B$16 -> 8.861145 | E30: =$B30-$C30-$D30 -> 872.82278 | F30: =K29 -> 3478.4612 | G30: =$F30*$B$8 -> 20.291024 | H30: =$B$12-$G30 -> 208.04913 | I30: =G30*(B30-C30) -> 17890.269 | J30: =$H30*($B30-$C30) -> 183433.57 | K30: =F30-H30 -> 3270.4121 | L30: =$D30*$K30 -> 28979.595 | M30: =$I30+$J30+$L30 -> 230303.44 | N30: =1/(1+$B$14)^A30 -> 0.98512424 | O30: =$M30*$N30 -> 226877.5
A31: 10 | B31: =$E30 -> 872.82278 | C31: =$B31*$B$15 -> 4.3641139 | D31: =$B31*$B$16 -> 8.7282278 | E31: =$B31-$C31-$D31 -> 859.73044 | F31: =K30 -> 3270.4121 | G31: =$F31*$B$8 -> 19.077404 | H31: =$B$12-$G31 -> 209.26275 | I31: =G31*(B31-C31) -> 16567.937 | J31: =$H31*($B31-$C31) -> 181736.05 | K31: =F31-H31 -> 3061.1493 | L31: =$D31*$K31 -> 26718.409 | M31: =$I31+$J31+$L31 -> 225022.39 | N31: =1/(1+$B$14)^A31 -> 0.9834851 | O31: =$M31*$N31 -> 221306.17
A32: 11 | B32: =$E31 -> 859.73044 | C32: =$B32*$B$15 -> 4.2986522 | D32: =$B32*$B$16 -> 8.5973044 | E32: =$B32-$C32-$D32 -> 846.83449 | F32: =K31 -> 3061.1493 | G32: =$F32*$B$8 -> 17.856704 | H32: =$B$12-$G32 -> 210.48345 | I32: =G32*(B32-C32) -> 15275.193 | J32: =$H32*($B32-$C32) -> 180054.23 | K32: =F32-H32 -> 2850.6659 | L32: =$D32*$K32 -> 24508.042 | M32: =$I32+$J32+$L32 -> 219837.47 | N32: =1/(1+$B$14)^A32 -> 0.98184868 | O32: =$M32*$N32 -> 215847.13
A33: 12 | B33: =$E32 -> 846.83449 | C33: =$B33*$B$15 -> 4.2341724 | D33: =$B33*$B$16 -> 8.4683449 | E33: =$B33-$C33-$D33 -> 834.13197 | F33: =K32 -> 2850.6659 | G33: =$F33*$B$8 -> 16.628884 | H33: =$B$12-$G33 -> 211.71127 | I33: =G33*(B33-C33) -> 14011.503 | J33: =$H33*($B33-$C33) -> 178387.98 | K33: =F33-H33 -> 2638.9546 | L33: =$D33*$K33 -> 22347.577 | M33: =$I33+$J33+$L33 -> 214747.06 | N33: =1/(1+$B$14)^A33 -> 0.98021499 | O33: =$M33*$N33 -> 210498.29
A34: 13 | B34: =$E33 -> 834.13197 | C34: =$B34*$B$15 -> 4.1706598 | D34: =$B34*$B$16 -> 8.3413197 | E34: =$B34-$C34-$D34 -> 821.61999 | F34: =K33 -> 2638.9546 | G34: =$F34*$B$8 -> 15.393902 | H34: =$B$12-$G34 -> 212.94625 | I34: =G34*(B34-C34) -> 12776.343 | J34: =$H34*($B34-$C34) -> 176737.15 | K34: =F34-H34 -> 2426.0083 | L34: =$D34*$K34 -> 20236.111 | M34: =$I34+$J34+$L34 -> 209749.6 | N34: =1/(1+$B$14)^A34 -> 0.97858402 | O34: =$M34*$N34 -> 205257.61
... A45: 24 | B45: =$E44 -> 706.37172 | C45: =$B45*$B$15 -> 3.5318586 | D45: =$B45*$B$16 -> 7.0637172 | E45: =$B45-$C45-$D45 -> 695.77614 | F45: =K44 -> 227.01589 | G45: =$F45*$B$8 -> 1.3242594 | H45: =$B$12-$G45 -> 227.01589 | I45: =G45*(B45-C45) -> 930.74228 | J45: =$H45*($B45-$C45) -> 159555.82 | K45: =F45-H45 -> 1.8900437e-11 | L45: =$D45*$K45 -> 1.3350734e-10 | M45: =$I45+$J45+$L45 -> 160486.56 | N45: =1/(1+$B$14)^A45 -> 0.96082143 | O45: =$M45*$N45 -> 154198.93
A46: Total | C46: =SUM($C$22:$C$45) -> 101.40795 | D46: =SUM($D$22:$D$45) -> 202.81591 | I46: =SUM(I22:I45) -> 337659.82 | J46: =SUM(J22:J45) -> 4270286.2 | L46: =SUM(L22:L45) -> 538836.72 | M46: =SUM(M22:M45) -> 5146782.7 | O46: =SUM(O22:O45) -> 5050507.6
A48: * Taking roundoff of Default and Prepayment to make it practical : Primary model uses expected (fractional) loan counts; the block below rounds to whole loans as a practicality check, and the $1,443 difference in PV confirms rounding is immaterial.
A49: Month t | B49: Loans at start | C49: Defaults (loans) | D49: Prepayments (loans) | E49: Loans at end | F49: Beginning balance per loan ($) | G49: Interest per loan ($) | H49: Scheduled principal per loan ($) | I49: AGGREGATE interest collected ($) | J49: AGGREGATE scheduled principal ($) | K49: Ending balance per loan ($) | L49: AGGREGATE prepayment principal ($) | M49: TOTAL cash to bank ($) | N49: Discount factor | O49: PV of cash ($)
A50: 1 | B50: =$B$5 -> 1000 | C50: =ROUND($B50*$B$15,0) -> 5 | D50: =ROUND($B50*$B$16,0) -> 10 | E50: =$B50-$C50-$D50 -> 985 | F50: =$B$10 -> 5100 | G50: =$F50*$B$8 -> 29.75 | H50: =$B$12-$G50 -> 198.59015 | I50: =G50*(B50-C50) -> 29601.25 | J50: =$H50*($B50-$C50) -> 197597.2 | K50: =F50-H50 -> 4901.4098 | L50: =$D50*$K50 -> 49014.098 | M50: =$I50+$J50+$L50 -> 276212.55 | N50: =1/(1+$B$14)^A50 -> 0.99833611 | O50: =$M50*$N50 -> 275752.96
A51: 2 | B51: =$E50 -> 985 | C51: =ROUND($B51*$B$15,0) -> 5 | D51: =ROUND($B51*$B$16,0) -> 10 | E51: =$B51-$C51-$D51 -> 970 | F51: =K50 -> 4901.4098 | G51: =$F51*$B$8 -> 28.591557 | H51: =$B$12-$G51 -> 199.7486 | I51: =G51*(B51-C51) -> 28019.726 | J51: =$H51*($B51-$C51) -> 195753.62 | K51: =F51-H51 -> 4701.6613 | L51: =$D51*$K51 -> 47016.613 | M51: =$I51+$J51+$L51 -> 270789.96 | N51: =1/(1+$B$14)^A51 -> 0.99667498 | O51: =$M51*$N51 -> 269889.58
A52: 3 | B52: =$E51 -> 970 | C52: =ROUND($B52*$B$15,0) -> 5 | D52: =ROUND($B52*$B$16,0) -> 10 | E52: =$B52-$C52-$D52 -> 955 | F52: =K51 -> 4701.6613 | G52: =$F52*$B$8 -> 27.426357 | H52: =$B$12-$G52 -> 200.9138 | I52: =G52*(B52-C52) -> 26466.435 | J52: =$H52*($B52-$C52) -> 193881.81 | K52: =F52-H52 -> 4500.7475 | L52: =$D52*$K52 -> 45007.475 | M52: =$I52+$J52+$L52 -> 265355.72 | N52: =1/(1+$B$14)^A52 -> 0.99501662 | O52: =$M52*$N52 -> 264033.35
A53: 4 | B53: =$E52 -> 955 | C53: =ROUND($B53*$B$15,0) -> 5 | D53: =ROUND($B53*$B$16,0) -> 10 | E53: =$B53-$C53-$D53 -> 940 | F53: =K52 -> 4500.7475 | G53: =$F53*$B$8 -> 26.25436 | H53: =$B$12-$G53 -> 202.08579 | I53: =G53*(B53-C53) -> 24941.642 | J53: =$H53*($B53-$C53) -> 191981.5 | K53: =F53-H53 -> 4298.6617 | L53: =$D53*$K53 -> 42986.617 | M53: =$I53+$J53+$L53 -> 259909.76 | N53: =1/(1+$B$14)^A53 -> 0.99336102 | O53: =$M53*$N53 -> 258184.23
A54: 5 | B54: =$E53 -> 940 | C54: =ROUND($B54*$B$15,0) -> 5 | D54: =ROUND($B54*$B$16,0) -> 9 | E54: =$B54-$C54-$D54 -> 926 | F54: =K53 -> 4298.6617 | G54: =$F54*$B$8 -> 25.075526 | H54: =$B$12-$G54 -> 203.26463 | I54: =G54*(B54-C54) -> 23445.617 | J54: =$H54*($B54-$C54) -> 190052.43 | K54: =F54-H54 -> 4095.397 | L54: =$D54*$K54 -> 36858.573 | M54: =$I54+$J54+$L54 -> 250356.62 | N54: =1/(1+$B$14)^A54 -> 0.99170817 | O54: =$M54*$N54 -> 248280.7
A55: 6 | B55: =$E54 -> 926 | C55: =ROUND($B55*$B$15,0) -> 5 | D55: =ROUND($B55*$B$16,0) -> 9 | E55: =$B55-$C55-$D55 -> 912 | F55: =K54 -> 4095.397 | G55: =$F55*$B$8 -> 23.889816 | H55: =$B$12-$G55 -> 204.45034 | I55: =G55*(B55-C55) -> 22002.521 | J55: =$H55*($B55-$C55) -> 188298.76 | K55: =F55-H55 -> 3890.9467 | L55: =$D55*$K55 -> 35018.52 | M55: =$I55+$J55+$L55 -> 245319.8 | N55: =1/(1+$B$14)^A55 -> 0.99005808 | O55: =$M55*$N55 -> 242880.85
...

Sheet Sheet 4 - Executive Summary
A1: MINI-PROJECT: THE TWO-LOAN COMPARISON
A2: Executive summary
A4: Recommended loan | B4: =IF(B18<C18,"Chase Bank",IF(C18<B18,"Wells Fargo Bank","Either loan")) -> Wells Fargo Bank
A5: Take the Wells Fargo loan. Despite the $100 origination fee, it is the cheaper loan on every measure that matters: lower monthly payment, lower total cash out, and a materially lower effective APR. The 3-percentage-point rate advantage is worth far more over 24 months than the 2% fee costs.
A9: Metric | B9: Chase | C9: Wells Fargo | D9: Advantage to Wells Fargo
A10: Cash received by the borrower ($) | B10: ='Sheet 1 - Amortization & Charts'!$B$19 -> 5000 | C10: ='Sheet 1 - Amortization & Charts'!$C$5 -> 5000 | D10: -
A11: Amount financed ($) | B11: ='Sheet 1 - Amortization & Charts'!$C$5 -> 5000 | C11: ='Sheet 1 - Amortization & Charts'!$J$19 -> 5100 | D11: =B11-C11 -> -100
A12: Monthly payment ($) | B12: ='Sheet 1 - Amortization & Charts'!$B$14 -> 230.72463 | C12: ='Sheet 1 - Amortization & Charts'!$D$14 -> 228.34015 | D12: =B12-C12 -> 2.3844783
A13: Total interest paid ($) | B13: ='Sheet 1 - Amortization & Charts'!$C$43 -> 537.39116 | C13: ='Sheet 1 - Amortization & Charts'!$K$43 -> 380.16368 | D13: =B13-C13 -> 157.22748
A14: Origination fee ($) | B14: =0 -> 0 | C14: ='Sheet 1 - Amortization & Charts'!$D$13-'Sheet 1 - Amortization & Charts'!$C$5 -> 100 | D14: =B14-C14 -> -100
A15: Interest plus fee ($) | B15: =SUM(B13:B14) -> 537.39116 | C15: =SUM(C13:C14) -> 480.16368 | D15: =B15-C15 -> 57.227478
A16: Effective monthly rate (IRR on cash received) | B16: =RATE('Sheet 1 - Amortization & Charts'!$A$42,-$B$12,'Sheet 4 - Executive Summary'!$B$10) -> 0.0083333333 | C16: =RATE('Sheet 1 - Amortization & Charts'!$I$42,-'Sheet 4 - Executive Summary'!$C$12,'Sheet 4 - Executive Summary'!$C$10) -> 0.0074696441 | D16: =B16-C16 -> 0.00086368922
A17: Effective APR - nominal (monthly IRR x 12) | B17: =B16*12 -> 0.1 | C17: =C16*12 -> 0.089635729 | D17: =B17-C17 -> 0.010364271 | E17: Effective APR is the monthly cash-flow rate multiplied by 12, using $5,000 received and 24 monthly payments. It includes the financed origination fee.
A18: Total payments ($) | B18: ='Sheet 1 - Amortization & Charts'!$D$43 -> 5537.3912 | C18: ='Sheet 1 - Amortization & Charts'!$L$43 -> 5480.1637 | D18: =B18-C18 -> 57.227478
A19: =IF(C18<B18,"Wells Fargo saves "&TEXT(D12,"$0.00")&" per month and "&TEXT(D18,"$0.00")&" over 24 months, including the fee.",IF(B18<C18,"Chase saves "&TEXT(-D12,"$0.00")&" per month and "&TEXT(-D18,"$0.00")&" over 24 months, including fees.","Both loans have the same total scheduled payments.")) -> Wells Fargo saves $2.38 per month and $57.23 over 24 months, including the fee.
